<?xml version="1.0" ?>
<robot name="AerialManipulator">

  <!-- To create a coordinate system for gripper -->
 <link name="endeffector"></link>
  <!-- Physical Bodies -->

  <!-- Mass properties of TwoBatteryAerialManipulator
       Configuration: Default
       Coordinate system: Vehicle

  Mass = 0.706028 kilograms

  Volume = 0.000938 cubic meters

  Surface area = 0.282960 square meters

  Center of mass: ( meters )
  	X = -0.000002
  	Y = -0.001101
  	Z = -0.001963

  Principal axes of inertia and principal moments of inertia: ( kilograms * square meters )
  Taken at the center of mass.
  	 Ix = (-0.002781, -0.999948, -0.009774)   	Px = 0.001720
  	 Iy = ( 0.999996, -0.002780, -0.000047)   	Py = 0.003063
  	 Iz = ( 0.000020, -0.009774,  0.999952)   	Pz = 0.004585

  Moments of inertia: ( kilograms * square meters )
  Taken at the center of mass and aligned with the output coordinate system. (Using positive tensor notation.)
  	Lxx = 0.003063	Lxy = 0.000004	Lxz = 0.000000
  	Lyx = 0.000004	Lyy = 0.001720	Lyz = 0.000028
  	Lzx = 0.000000	Lzy = 0.000028	Lzz = 0.004585

  Moments of inertia: ( kilograms * square meters )
  Taken at the output coordinate system. (Using positive tensor notation.)
  	Ixx = 0.003067	Ixy = 0.000004	Ixz = 0.000000
  	Iyx = 0.000004	Iyy = 0.001723	Iyz = 0.000030
  	Izx = 0.000000	Izy = 0.000030	Izz = 0.004586

  One or more components have overridden mass properties:
  	HalfBattery<1><Default>
  	HalfBattery<2><Default>
  	moteus.step<1><Default>
  	VOXL<1><Default>
  	IQ2306@Thruster_CW
  	IQ2306@Thruster_CW
  	IQ2306@Thruster_CW
  	IQ2306@Thruster_CW
  	MatekPDB<1><Default>
  	Antigravity5008@ShoulderJoint -->


  <link name="virtualvehicle">
    <!-- <inertial>
      <mass value="0.0000000000001"/>
      <inertia ixx="0.0000000000001" ixy="0.0" ixz="0.0" iyy="0.0000000000001" iyz="0.0" izz="0.0000000000001"/>
    </inertial> -->
    <visual>
      <origin rpy="0 0 0" xyz="0 0 0"/>
      <geometry>
        <sphere radius="0.03"/>
      </geometry>
      <material name="red">
            <color rgba="1 0 0 1"/>
      </material>
    </visual>

    <!-- Spine -->
    <visual>
      <origin xyz="0 0 0" rpy="1.57079632679 0 0" />
      <geometry>
        <cylinder radius=".009" length=".036"/>
      </geometry>
      <material name="tmotor">
        <color rgba="0.4 0.4 0.4 1.0"/>
      </material>
    </visual>
    <!-- Printed Mounts -->
    <visual>
      <origin xyz="0 .0205 0" rpy="0 0 0" />
      <geometry>
        <box size=".048 .005 .02" />
      </geometry>
      <material name="print">
        <color rgba="0.9 0.9 0.9 1.0"/>
      </material>
    </visual>
    <visual>
      <origin xyz="0 -.0205 0" rpy="0 0 0" />
      <geometry>
        <box size=".048 .005 .02" />
      </geometry>
      <material name="print">
        <color rgba="0.9 0.9 0.9 1.0"/>
      </material>
    </visual>
    <!-- Plates -->
    <visual>
      <origin xyz="0 .061 -.0115" rpy="0 0 0" />
      <geometry>
        <box size=".048 .086 .003" />
      </geometry>
      <material name="carbon">
        <color rgba="0.2 0.2 0.2 1.0"/>
      </material>
    </visual>
    <visual>
      <origin xyz="0 -.061 -.0115" rpy="0 0 0" />
      <geometry>
        <box size=".048 .086 .003" />
      </geometry>
      <material name="carbon">
        <color rgba="0.2 0.2 0.2 1.0"/>
      </material>
    </visual>
    <visual>
      <origin xyz="0 .061 -.0345" rpy="0 0 0" />
      <geometry>
        <box size=".048 .086 .003" />
      </geometry>
      <material name="carbon">
        <color rgba="0.2 0.2 0.2 1.0"/>
      </material>
    </visual>
    <visual>
      <origin xyz="0 -.061 -.0345" rpy="0 0 0" />
      <geometry>
        <box size=".048 .086 .003" />
      </geometry>
      <material name="carbon">
        <color rgba="0.2 0.2 0.2 1.0"/>
      </material>
    </visual>
    <!-- Standoffs -->
    <visual>
      <origin xyz=".02 .022 -.023" rpy="0 0 0" />
      <geometry>
        <cylinder radius=".002" length=".020"/>
      </geometry>
      <material name="tmotor">
        <color rgba="0.4 0.4 0.4 1.0"/>
      </material>
    </visual>
    <visual>
      <origin xyz=".02 -.022 -.023" rpy="0 0 0" />
      <geometry>
        <cylinder radius=".002" length=".020"/>
      </geometry>
      <material name="tmotor">
        <color rgba="0.4 0.4 0.4 1.0"/>
      </material>
    </visual>
    <visual>
      <origin xyz="-.02 .022 -.023" rpy="0 0 0" />
      <geometry>
        <cylinder radius=".002" length=".020"/>
      </geometry>
      <material name="tmotor">
        <color rgba="0.4 0.4 0.4 1.0"/>
      </material>
    </visual>
    <visual>
      <origin xyz="-.02 -.022 -.023" rpy="0 0 0" />
      <geometry>
        <cylinder radius=".002" length=".020"/>
      </geometry>
      <material name="tmotor">
        <color rgba="0.4 0.4 0.4 1.0"/>
      </material>
    </visual>
    <visual>
      <origin xyz=".02 .099 -.023" rpy="0 0 0" />
      <geometry>
        <cylinder radius=".002" length=".020"/>
      </geometry>
      <material name="tmotor">
        <color rgba="0.4 0.4 0.4 1.0"/>
      </material>
    </visual>
    <visual>
      <origin xyz=".02 -.099 -.023" rpy="0 0 0" />
      <geometry>
        <cylinder radius=".002" length=".020"/>
      </geometry>
      <material name="tmotor">
        <color rgba="0.4 0.4 0.4 1.0"/>
      </material>
    </visual>
    <visual>
      <origin xyz="-.02 .099 -.023" rpy="0 0 0" />
      <geometry>
        <cylinder radius=".002" length=".020"/>
      </geometry>
      <material name="tmotor">
        <color rgba="0.4 0.4 0.4 1.0"/>
      </material>
    </visual>
    <visual>
      <origin xyz="-.02 -.099 -.023" rpy="0 0 0" />
      <geometry>
        <cylinder radius=".002" length=".020"/>
      </geometry>
      <material name="tmotor">
        <color rgba="0.4 0.4 0.4 1.0"/>
      </material>
    </visual>
    <!-- Saddle -->
    <visual>
      <origin xyz="0 0 -.031" rpy="0 0 0" />
      <geometry>
        <box size=".009 .0455 .004" />
      </geometry>
      <material name="carbon">
        <color rgba="0.2 0.2 0.2 1.0"/>
      </material>
    </visual>
    <!-- Shoulder Motor -->
    <visual>
      <origin xyz="0 0 0" rpy="1.57079632679 0 0" />
      <geometry>
        <cylinder radius=".0278" length=".015"/>
      </geometry>
      <material name="tmotor">
        <color rgba="0.4 0.4 0.4 1.0"/>
      </material>
    </visual>
    <!-- Arms -->
    <visual>
      <origin xyz=".057025 .062426 -0.008" rpy="0 0 0.575959" />
      <geometry>
        <box size=".100 .014 .004" />
      </geometry>
      <material name="carbon">
        <color rgba="0.2 0.2 0.2 1.0"/>
      </material>
    </visual>
    <visual>
      <origin xyz=".057025 -.062426 -0.008" rpy="0 0 -0.575959" />
      <geometry>
        <box size=".100 .014 .004" />
      </geometry>
      <material name="carbon">
        <color rgba="0.2 0.2 0.2 1.0"/>
      </material>
    </visual>
    <visual>
      <origin xyz="-.057025 .062426 -0.008" rpy="0 0 -0.575959" />
      <geometry>
        <box size=".100 .014 .004" />
      </geometry>
      <material name="carbon">
        <color rgba="0.2 0.2 0.2 1.0"/>
      </material>
    </visual>
    <visual>
      <origin xyz="-.057025 -.062426 -0.008" rpy="0 0 0.575959" />
      <geometry>
        <box size=".100 .014 .004" />
      </geometry>
      <material name="carbon">
        <color rgba="0.2 0.2 0.2 1.0"/>
      </material>
    </visual>
    <!-- Battery -->
    <visual>
      <origin xyz="0 .060 0" rpy="0 0 0" />
      <geometry>
        <box size=".036 .071 .022" />
      </geometry>
      <material name="battery">
        <color rgba="0.2 0.5 0.5 1.0"/>
      </material>
    </visual>
    <visual>
      <origin xyz="0 -.060 0" rpy="0 0 0" />
      <geometry>
        <box size=".036 .071 .022" />
      </geometry>
      <material name="battery">
        <color rgba="0.2 0.5 0.5 1.0"/>
      </material>
    </visual>

  </link>

<!-- Mass properties of ArmJointElbow
     Configuration: Default
     Coordinate system: Link1

Mass = 0.053412 kilograms

Volume = 0.000024 cubic meters

Surface area = 0.011362 square meters

Center of mass: ( meters )
	X = -0.000157
	Y = -0.000377
	Z = 0.055676

Principal axes of inertia and principal moments of inertia: ( kilograms * square meters )
Taken at the center of mass.
	 Ix = (-0.000110, -0.063379, -0.997990)   	Px = 0.000005
	 Iy = (-0.991262, -0.131635,  0.008469)   	Py = 0.000021
	 Iz = (-0.131907,  0.989270, -0.062810)   	Pz = 0.000021

Moments of inertia: ( kilograms * square meters )
Taken at the center of mass and aligned with the output coordinate system. (Using positive tensor notation.)
	Lxx = 0.000021	Lxy = 0.000000	Lxz = 0.000000
	Lyx = 0.000000	Lyy = 0.000021	Lyz = 0.000001
	Lzx = 0.000000	Lzy = 0.000001	Lzz = 0.000005

Moments of inertia: ( kilograms * square meters )
Taken at the output coordinate system. (Using positive tensor notation.)
	Ixx = 0.000186	Ixy = 0.000000	Ixz = 0.000000
	Iyx = 0.000000	Iyy = 0.000186	Iyz = 0.000000
	Izx = 0.000000	Izy = 0.000000	Izz = 0.000005

One or more components have overridden mass properties:
	IQ2306 Simplified<1><Default>
	WristSlipRing<1><Default>
 -->

  <link name="link1">
    <inertial>
      <mass value=".053412"/>
      <inertia ixx="0.000021" ixy="0.000000" ixz="0.000000" iyy="0.000021" iyz="0.000001" izz="0.000005"/>
      <origin rpy=" 0 0 0" xyz="0 0 0.053412"/>
    </inertial>
    <visual>
      <origin rpy=" 0 0 0" xyz="0 0 0.053412"/>
      <geometry>
        <sphere radius="0.005"/>
      </geometry>
      <material name="green">
            <color rgba="0 1 0 1"/>
      </material>
    </visual>
    <visual>
      <origin xyz="0 -.0095 -0.1402" rpy="0 0 0" />
      <geometry>
        <box size=".009 .004 .041" />
      </geometry>
      <material name="carbon">
        <color rgba="0.2 0.2 0.2 1.0"/>
      </material>
    </visual>
    <!-- Wrist Motor -->
    <visual>
      <origin xyz="0 0 -0.1087" rpy="0 0 0" />
      <geometry>
        <cylinder radius=".0142" length="0.022"/>
      </geometry>
      <material name="motor" />
    </visual>
    <!-- Carbon Fiber Tube -->
    <visual>
      <origin xyz="0 0 -0.0407" rpy="0 0 0" />
      <geometry>
        <cylinder radius=".0075" length="0.115"/>
      </geometry>
      <material name="carbon" />
    </visual>
  </link>





<!-- Mass properties of TubeArm
     Configuration: Default
     Coordinate system: Link2

Mass = 0.07583633 kilograms

Volume = 35944.59940832 cubic millimeters

Surface area = 0.02060674 square meters

Center of mass: ( meters )
	X = -0.00104910
	Y = -0.00076015
	Z = 0.12635585

Principal axes of inertia and principal moments of inertia: ( kilograms * square meters )
Taken at the center of mass.
	 Ix = (-0.00001265,  0.00019616,  0.99999998)   	Px = 0.00000767
	 Iy = ( 0.99976690, -0.02159048,  0.00001688)   	Py = 0.00010771
	 Iz = ( 0.02159048,  0.99976688, -0.00019584)   	Pz = 0.00011016

Moments of inertia: ( kilograms * square meters )
Taken at the center of mass and aligned with the output coordinate system. (Using positive tensor notation.)
	Lxx = 0.00010771	Lxy = -0.00000005	Lxz = 0.00000000
	Lyx = -0.00000005	Lyy = 0.00011016	Lyz = 0.00000002
	Lzx = 0.00000000	Lzy = 0.00000002	Lzz = 0.00000767

Moments of inertia: ( kilograms * square meters )
Taken at the output coordinate system. (Using positive tensor notation.)
	Ixx = 0.00131854	Ixy = 0.00000000	Ixz = -0.00001005
	Iyx = 0.00000000	Iyy = 0.00132103	Iyz = -0.00000726
	Izx = -0.00001005	Izy = -0.00000726	Izz = 0.00000780

One or more components have overridden mass properties:
	Ball<1><Default>
	assembled_gripper_1_1.step<1><Default>@MicroGripper<1><Default>
 -->



  <link name="link2">
    <inertial>
      <mass value="0.07583633"/>
      <inertia ixx="0.00010771" ixy="-0.00000005" ixz="0.00000000" iyy=" 0.00011016" iyz="0.00000002" izz="0.00000767"/>
      <origin rpy=" 0 0 0" xyz="0 0 -0.12635585 "/>
      <!-- ignored offsets in other directions -->
    </inertial>
    <visual>
      <origin rpy=" 0 0 0" xyz="0 0 -0.12635585"/>
      <geometry>
        <sphere radius="0.03"/>
      </geometry>
      <material name="blue">
            <color rgba="0 0 1 1"/>
      </material>
    </visual>

    <!-- Gripper Palm -->
    <visual>
      <origin xyz="0 0 -.0207" rpy="0 0 0" />
      <geometry>
        <box size=".04 .022 .01" />
      </geometry>
      <material name="carbon">
        <color rgba="0.2 0.2 0.2 1.0"/>
      </material>
    </visual>
    <!-- Servo -->
    <visual>
      <origin xyz="0 0 -0.0357" rpy="0 0 0" />
      <geometry>
        <box size=".03 .015 .02" />
      </geometry>
      <material name="tmotor">
        <color rgba="0.4 0.4 0.4 1.0"/>
      </material>
    </visual>
    <!-- Finger -->
    <visual>
      <origin xyz=".018 0 -.0007" rpy="0 0 0" />
      <geometry>
        <box size=".004 .022 .03" />
      </geometry>
      <material name="tip">
        <color rgba="0.7 0.3 0.3 1.0"/>
      </material>
    </visual>
    <!-- Finger -->
    <visual>
      <origin xyz="-.018 0 -.0007" rpy="0 0 0" />
      <geometry>
        <box size=".004 .022 .03" />
      </geometry>
      <material name="tip">
        <color rgba="0.7 0.3 0.3 1.0"/>
      </material>
    </visual>
  </link>

  <link name="vehicle">
    <inertial>
      <mass value="0.83527633"/> <!-- 0.706028   83527633 -->
      <inertia ixx="0.003063" ixy="0.000004" ixz="0.000000" iyy="0.001720" iyz="0.000028" izz="0.004585"/>
      <origin rpy="0 0 0" xyz="-1.8626e-09  2.2484e-02 6.7184e-09"/>
    </inertial>
  </link>

  <link name="COM">
  </link>



  <!-- Physical Joints -->

  <joint name="yawfix" type="fixed" dont_collapse="true">
    <parent link="virtualvehicle"/>
    <child link="vehicle"/>
    <origin rpy="0 0 1.57079632679" xyz="0 0 0"/>
  </joint>

  <joint name="com_offset" type="fixed" dont_collapse="true">
    <parent link="endeffector"/>
    <child link="COM"/>
    <origin rpy="0 0 0" xyz="0 -2.00715814e-01 -1.59835415e-04"/>
  </joint>

  <joint name="joint1" type="continuous">
  <!-- <joint name="joint1" type="fixed" dont_collapse="true"> -->
    <parent link="link1"/>
    <child link="vehicle"/>
    <axis rpy="0 0 0" xyz="0 1 0"/>
    <origin rpy="0 1.57079632679 0" xyz="0 0 -.1607"/>
    <limit velocity="1e9" effort=".9" lower="-3.0" upper="3.0" />
  </joint>
  <!-- <joint name="joint2" type="continuous"> -->
  <joint name="joint2" type="fixed" dont_collapse="true">
    <parent link="link2"/>
    <child link="link1"/>
    <origin rpy="0 0 -1.57079632679" xyz=" 0 0 -.0625"/>
    <axis rpy="0 0 0" xyz="0 0 1"/>
    <limit velocity="1e9" effort=".1" lower="-3.1415926" upper="3.1415926" />
  </joint>


  <!-- <transmission name="joint2">
    <type>transmission_interface/SimpleTransmission</type>
    <joint name="joint2">
      <hardwareInterface>EffortJointInterface</hardwareInterface>
    </joint>
    <actuator name="joint2">
      <mechanicalReduction>1</mechanicalReduction>
      <hardwareInterface>EffortJointInterface</hardwareInterface>
    </actuator>
  </transmission>

  <transmission name="joint1">
    <type>transmission_interface/SimpleTransmission</type>
    <joint name="joint1">
      <hardwareInterface>EffortJointInterface</hardwareInterface>
    </joint>
    <actuator name="joint1">
      <mechanicalReduction>1</mechanicalReduction>
      <hardwareInterface>EffortJointInterface</hardwareInterface>
    </actuator>
  </transmission> -->


  <joint name="jointend" type="fixed">
    <parent link="endeffector"/>
    <child link="link2"/>
    <origin rpy="-1.57 0 0" xyz="0 0 0"/>
    <!-- <origin rpy="-1.57079632679 0 -1.57079632679" xyz="0 0 -.1607"/> -->
    <!-- <origin rpy="-1.57079632679 0 -1.57079632679" xyz="0 0 -.1607"/> -->
  </joint>





  <material name="wash">
    <color rgba="1 0 0 .15"/>
  </material>
  <material name="prop">
    <color rgba="1 0 0 1"/>
  </material>

  <!-- Motors -->
  <material name="motor">
    <color rgba="0.5 0.5 .5 1.0"/>
  </material>

  <link name="motor1">
    <visual>
      <origin xyz="0 0 0" rpy="0 0 0" />
      <geometry>
        <cylinder radius=".0142" length="0.022"/>
      </geometry>
      <material name="motor" />
    </visual>
  </link>
  <link name="motor2">
    <visual>
      <origin xyz="0 0 0" rpy="0 0 0" />
      <geometry>
        <cylinder radius=".0142" length="0.022"/>
      </geometry>
      <material name="motor" />
    </visual>
  </link>
  <link name="motor3">
    <visual>
      <origin xyz="0 0 0" rpy="0 0 0" />
      <geometry>
        <cylinder radius=".0142" length="0.022"/>
      </geometry>
      <material name="motor" />
    </visual>
  </link>
  <link name="motor4">
    <visual>
      <origin xyz="0 0 0" rpy="0 0 0" />
      <geometry>
        <cylinder radius=".0142" length="0.022"/>
      </geometry>
      <material name="motor" />
    </visual>
  </link>

  <link name="prop1">
    <visual>
      <origin xyz="0 0 0" rpy="0 0 0" />
      <geometry>
        <cylinder radius=".06477" length="0.007"/>
      </geometry>
      <material name="wash" />
    </visual>
  </link>
  <link name="prop2">
    <visual>
      <origin xyz="0 0 0" rpy="0 0 0" />
      <geometry>
        <cylinder radius=".06477" length="0.007"/>
      </geometry>
      <material name="wash" />
    </visual>
  </link>
  <link name="prop3">
    <visual>
      <origin xyz="0 0 0" rpy="0 0 0" />
      <geometry>
        <cylinder radius=".06477" length="0.007"/>
      </geometry>
      <material name="wash" />
    </visual>
  </link>
  <link name="prop4">
    <visual>
      <origin xyz="0 0 0" rpy="0 0 0" />
      <geometry>
        <cylinder radius=".06477" length="0.007"/>
      </geometry>
      <material name="wash" />
    </visual>
  </link>




  <joint name="motor1" type="fixed" dont_collapse="true">
    <parent link="vehicle"/>
    <child link="motor1"/>
    <origin xyz=".09057 .084212 .004" rpy="0 0 0" />
  </joint>
  <joint name="motor2" type="fixed" dont_collapse="true">
    <parent link="vehicle"/>
    <child link="motor2"/>
    <origin xyz="-.09057 .084212 .004" rpy="0 0 0" />
  </joint>
  <joint name="motor3" type="fixed" dont_collapse="true">
    <parent link="vehicle"/>
    <child link="motor3"/>
    <origin xyz="-.09057 -.084212 .004" rpy="0 0 0" />
  </joint>
  <joint name="motor4" type="fixed" dont_collapse="true">
    <parent link="vehicle"/>
    <child link="motor4"/>
    <origin xyz=".09057 -.084212 .004" rpy="0 0 0" />
  </joint>

  <joint name="prop1" type="continuous">
    <parent link="motor1"/>
    <child link="prop1"/>
    <origin xyz="0 0 .016" rpy="0 0 0"/>
    <axis rpy="0 0 0" xyz="0 0 1"/>
    <propeller kf="1e-1" km="1e-2" min="-100" max="100"/>
  </joint>
  <joint name="prop2" type="continuous">
    <parent link="motor2"/>
    <child link="prop2"/>
    <origin xyz="0 0 .016" rpy="0 0 0"/>
    <axis rpy="0 0 0" xyz="0 0 1"/>
    <propeller kf="1e-1" km="-1e-2" min="-100" max="100"/>
  </joint>
  <joint name="prop3" type="continuous">
    <parent link="motor3"/>
    <child link="prop3"/>
    <origin xyz="0 0 .016" rpy="0 0 0"/>
    <axis rpy="0 0 0" xyz="0 0 1"/>
    <propeller kf="1e-1" km="1e-2" min="-100" max="100"/>
  </joint>
  <joint name="prop4" type="continuous">
    <parent link="motor4"/>
    <child link="prop4"/>
    <origin xyz="0 0 .016" rpy="0 0 0"/>
    <axis rpy="0 0 0" xyz="0 0 1"/>
    <propeller kf="1e-1" km="-1e-2" min="-100" max="100"/>
  </joint>



  <!--

   Uncomment below to view this URDF with rviz. (Needs a base link with no inertia)

   Run the following command to visualize and manipulate the joints:

   roslaunch urdf_tutorial display.launch model:=aerialmanipulator.urdf

   (must be in same directory as this file, called aerialmanipulator.urdf)

 -->

  <!-- <link name="base_link"></link>
  <joint name="world" type="fixed">
    <parent link="base_link"/>
    <child link="endeffector"/>
    <origin rpy="0 0 0" xyz=" 0 0 0"/>
  </joint> -->



</robot>
