<?xml version="1.0" ?>
<robot name="AerialManipulator">

  <link name="endeffector">
  <inertial>
      <!-- <mass value="0.2"/> -->
  </inertial>
 </link>

  <link name="gripper">
    <inertial>
      <!-- <mass value="0.2"/> -->
    </inertial>
    <visual>
      <origin xyz="0 0 -.0207" rpy="0 0 0" />
      <geometry>
        <box size=".04 .022 .01" />
      </geometry>
      <material name="carbon">
        <color rgba="0.2 0.2 0.2 1.0"/>
      </material>
    </visual>
    <!-- Servo -->
    <visual>
      <origin xyz="0 0 -0.0357" rpy="0 0 0" />
      <geometry>
        <box size=".03 .015 .02" />
      </geometry>
      <material name="tmotor">
        <color rgba="0.4 0.4 0.4 1.0"/>
      </material>
    </visual>
    <!-- Finger -->
    <visual>
      <origin xyz=".018 0 -.0007" rpy="0 0 0" />
      <geometry>
        <box size=".004 .022 .03" />
      </geometry>
      <material name="tip">
        <color rgba="0.7 0.3 0.3 1.0"/>
      </material>
    </visual>
    <!-- Finger -->
    <visual>
      <origin xyz="-.018 0 -.0007" rpy="0 0 0" />
      <geometry>
        <box size=".004 .022 .03" />
      </geometry>
      <material name="tip">
        <color rgba="0.7 0.3 0.3 1.0"/>
      </material>
    </visual>
  </link>

 <link name="vehicle">
    <inertial>
      <!-- <mass value="1.0"/> -->
      <inertia ixx="0.001" ixy="0.0" ixz="0.0" iyy=" 0.001" iyz="0.0" izz="0.003"/>
      <origin rpy=" 0 0 0" xyz="0 0.05 0"/>
      <mass value="0.8"/>
    </inertial>
    <visual>
      <origin xyz=".1 .1 0" rpy="0 0 0" />
      <geometry>
        <cylinder radius=".06477" length="0.007"/>
      </geometry>
      <material name="wash" />
    </visual>
    <visual>
      <origin xyz="-.1 .1 0" rpy="0 0 0" />
      <geometry>
        <cylinder radius=".06477" length="0.007"/>
      </geometry>
      <material name="wash" />
    </visual>
    <visual>
      <origin xyz="-.1 -.1 0" rpy="0 0 0" />
      <geometry>
        <cylinder radius=".06477" length="0.007"/>
      </geometry>
      <material name="wash" />
    </visual>
    <visual>
      <origin xyz=".1 -.1 0" rpy="0 0 0" />
      <geometry>
        <cylinder radius=".06477" length="0.007"/>
      </geometry>
      <material name="wash" />
    </visual>
    <visual>
      <origin xyz="0 .1 0" rpy="1.57068 0 0" />
      <geometry>
        <cylinder radius=".01" length="0.2"/>
      </geometry>
      <material name="wash" />
    </visual>
 </link>

<link name="COM">
  <inertial>
      <!-- <mass value="1.0"/> -->
      <!-- <inertia ixx="0.00001" ixy="0.0" ixz="0.0" iyy=" 0.01" iyz="0.0" izz="0.00001"/> -->
    </inertial>
 </link>

  <joint name="offset" type="fixed" dont_collapse="true">
    <parent link="endeffector"/>
    <child link="vehicle"/>
    <origin rpy="0 0 0" xyz="0 -0.25 0"/>
  </joint>

  <joint name="com_offset" type="fixed" dont_collapse="true">
    <parent link="endeffector"/>
    <child link="COM"/>
    <origin rpy="0 0 0" xyz="0 -0.2 0"/>
  </joint>

  <link name="propeller1"></link>
  <link name="propeller2"></link>
  <link name="propeller3"></link>
  <link name="propeller4"></link>

  <joint name="prop1" type="continuous">
    <parent link="vehicle"/>
    <child link="propeller1"/>
    <origin xyz=".1 .1 0" rpy="0 0 0"/>
    <axis rpy="0 0 0" xyz="0 0 1"/>
  </joint>
  <joint name="prop2" type="continuous">
    <parent link="vehicle"/>
    <child link="propeller2"/>
    <origin xyz="-.1 .1 0" rpy="0 0 0"/>
    <axis rpy="0 0 0" xyz="0 0 1"/>
  </joint>
  <joint name="prop3" type="continuous">
    <parent link="vehicle"/>
    <child link="propeller3"/>
    <origin xyz="-.1 -.1 0" rpy="0 0 0"/>
    <axis rpy="0 0 0" xyz="0 0 1"/>
  </joint>
  <joint name="prop4" type="continuous">
    <parent link="vehicle"/>
    <child link="propeller4"/>
    <origin xyz=".1 -.1 0" rpy="0 0 0"/>
    <axis rpy="0 0 0" xyz="0 0 1"/>
  </joint>

</robot>
