<?xml version="1.0" ?>
<robot name="CrazyflieBL">

<link name="body">
    <inertial>
        <mass value="0.039"/>
        <inertia ixx="3e-5" ixy="0.0" ixz="0.0" iyy="3e-5" iyz="0.0" izz="3.5e-5"/>
    </inertial>

    <visual>
        <origin xyz="0 0 0" rpy="0 0 0"/>
        <geometry>
            <mesh filename="./CF21-BL.stl" scale="0.001 0.001 0.001"/>
        </geometry>
    </visual>
    <collision>
        <origin xyz="0 0 0" rpy="0 0 0"/>
         <geometry>
            <mesh filename="./CF21-BL.stl" scale="0.001 0.001 0.001"/>
        </geometry>
    </collision>
</link>

<link name="COM">
    <inertial>
        <mass value="0.0000000000001"/>
        <inertia ixx="0.0000000000001" ixy="0.0" ixz="0.0" iyy="0.0000000000001" iyz="0.0" izz="0.0000000000001"/>
    </inertial>
</link>

<link name="prop1">
    <inertial>
        <mass value="0.0000000000001"/>
        <inertia ixx="0.0000000000001" ixy="0.0" ixz="0.0" iyy="0.0000000000001" iyz="0.0" izz="0.0000000000001"/>
    </inertial>
</link>
    <inertial>
        <mass value="0.0000000000001"/>
        <inertia ixx="0.0000000000001" ixy="0.0" ixz="0.0" iyy="0.0000000000001" iyz="0.0" izz="0.0000000000001"/>
    </inertial>
<link name="prop2">
    <inertial>
        <mass value="0.0000000000001"/>
        <inertia ixx="0.0000000000001" ixy="0.0" ixz="0.0" iyy="0.0000000000001" iyz="0.0" izz="0.0000000000001"/>
    </inertial>
</link>
<link name="prop3">
    <inertial>
        <mass value="0.0000000000001"/>
        <inertia ixx="0.0000000000001" ixy="0.0" ixz="0.0" iyy="0.0000000000001" iyz="0.0" izz="0.0000000000001"/>
    </inertial>
</link>
<link name="prop4">
    <inertial>
        <mass value="0.0000000000001"/>
        <inertia ixx="0.0000000000001" ixy="0.0" ixz="0.0" iyy="0.0000000000001" iyz="0.0" izz="0.0000000000001"/>
    </inertial>
</link>


<joint name="com" type="fixed" dont_collapse="true">
    <parent link="body"/>
    <child link="COM"/>
    <origin xyz="0 0 0" rpy="0 0 0"/>
</joint>

<joint name="m1_joint" type="continuous">
    <parent link="body"/>
    <child link="prop1"/>
    <origin xyz="0 0 0.01" rpy="0 0 0"/>
    <axis rpy="0 0 0" xyz="0 0 1"/>
</joint>
<joint name="m2_joint" type="continuous">
    <parent link="body"/>
    <child link="prop2"/>
    <origin xyz="0 0 0.01" rpy="0 0 0"/>
    <axis rpy="0 0 0" xyz="0 0 1"/>
</joint>
<joint name="m3_joint" type="continuous">
    <parent link="body"/>
    <child link="prop3"/>
    <origin xyz="0 0 0.01" rpy="0 0 0"/>
    <axis rpy="0 0 0" xyz="0 0 1"/>
</joint>
<joint name="m4_joint" type="continuous">
    <parent link="body"/>
    <child link="prop4"/>
    <origin xyz="0 0 0.01" rpy="0 0 0"/>
    <axis rpy="0 0 0" xyz="0 0 1"/>
</joint>

</robot>